Workbook

Sheet 01_input_asset_master
A1: property_id | B1: property_name | C1: city | D1: county | E1: state | F1: property_type | G1: year_built | H1: gross_floor_area_sqft | I1: units | J1: occupancy_rate | K1: affordable_units_pct
A2: WI-MF-01 | B2: Riverbend Apartments | C2: Madison | D2: Dane | E2: WI | F2: Multifamily | G2: 1988 | H2: 165000 | I2: 180 | J2: 0.94 | K2: 0.25
A3: WI-MF-02 | B3: Lakeview Terrace | C3: Milwaukee | D3: Milwaukee | E3: WI | F3: Multifamily | G3: 1975 | H3: 220000 | I3: 240 | J3: 0.91 | K3: 0.6
A4: WI-MF-03 | B4: Northside Commons | C4: Green Bay | D4: Brown | E4: WI | F4: Multifamily | G4: 1995 | H4: 145000 | I4: 160 | J4: 0.96 | K4: 0.15
A5: WI-MF-04 | B5: Badger Ridge Homes | C5: Wausau | D5: Marathon | E5: WI | F5: Multifamily | G5: 1982 | H5: 120000 | I5: 130 | J5: 0.93 | K5: 0.4
A6: WI-MF-05 | B6: Oak Street Lofts | C6: Eau Claire | D6: Eau Claire | E6: WI | F6: Multifamily | G6: 2008 | H6: 98000 | I6: 105 | J6: 0.97 | K6: 0.1
A7: WI-MF-06 | B7: South Park Apartments | C7: Racine | D7: Racine | E7: WI | F7: Multifamily | G7: 1970 | H7: 185000 | I7: 210 | J7: 0.89 | K7: 0.55
A8: WI-MF-07 | B8: Fox River Flats | C8: Appleton | D8: Outagamie | E8: WI | F8: Multifamily | G8: 2001 | H8: 135000 | I8: 150 | J8: 0.95 | K8: 0.2
A9: WI-MF-08 | B9: Prairie View Residences | C9: La Crosse | D9: La Crosse | E9: WI | F9: Multifamily | G9: 1990 | H9: 110000 | I9: 120 | J9: 0.92 | K9: 0.35
A10: WI-MF-09 | B10: Capitol Square Homes | C10: Madison | D10: Dane | E10: WI | F10: Multifamily | G10: 2015 | H10: 175000 | I10: 190 | J10: 0.98 | K10: 0.05
A11: WI-MF-10 | B11: Harbor Point Apartments | C11: Kenosha | D11: Kenosha | E11: WI | F11: Multifamily | G11: 1980 | H11: 160000 | I11: 175 | J11: 0.9 | K11: 0.5

Sheet 02_input_energy_monthly
A1: property_id | B1: property_name | C1: city | D1: county | E1: state | F1: property_type | G1: month | H1: electricity_kwh | I1: natural_gas_therms | J1: electricity_cost_usd | K1: natural_gas_cost_usd | L1: electricity_rate_usd_kwh | M1: gas_rate_usd_therm | N1: owner_or_tenant_paid | O1: data_quality | P1: source_note
A2: WI-MF-01 | B2: Riverbend Apartments | C2: Madison | D2: Dane | E2: WI | F2: Multifamily | G2: 2025-01 | H2: 90495 | I2: 10534 | J2: 13121.77 | K2: 11587.4 | L2: 0.145 | M2: 1.1 | N2: Mixed / simulated | O2: Simulated from ENERGY STAR multifamily EUI benchmark; not actual utility bills | P2: ENERGY STAR Portfolio Manager Data Explorer / U.S. National Median EUI table
A3: WI-MF-01 | B3: Riverbend Apartments | C3: Madison | D3: Dane | E3: WI | F3: Multifamily | G3: 2025-02 | H3: 83708 | I3: 8826 | J3: 12137.66 | K3: 9708.6 | L3: 0.145 | M3: 1.1 | N3: Mixed / simulated | O3: Simulated from ENERGY STAR multifamily EUI benchmark; not actual utility bills | P3: ENERGY STAR Portfolio Manager Data Explorer / U.S. National Median EUI table
A4: WI-MF-01 | B4: Riverbend Apartments | C4: Madison | D4: Dane | E4: WI | F4: Multifamily | G4: 2025-03 | H4: 84839 | I4: 7402 | J4: 12301.65 | K4: 8142.2 | L4: 0.145 | M4: 1.1 | N4: Mixed / simulated | O4: Simulated from ENERGY STAR multifamily EUI benchmark; not actual utility bills | P4: ENERGY STAR Portfolio Manager Data Explorer / U.S. National Median EUI table
A5: WI-MF-01 | B5: Riverbend Apartments | C5: Madison | D5: Dane | E5: WI | F5: Multifamily | G5: 2025-04 | H5: 84839 | I5: 4555 | J5: 12301.65 | K5: 5010.5 | L5: 0.145 | M5: 1.1 | N5: Mixed / simulated | O5: Simulated from ENERGY STAR multifamily EUI benchmark; not actual utility bills | P5: ENERGY STAR Portfolio Manager Data Explorer / U.S. National Median EUI table
A6: WI-MF-01 | B6: Riverbend Apartments | C6: Madison | D6: Dane | E6: WI | F6: Multifamily | G6: 2025-05 | H6: 92757 | I6: 2562 | J6: 13449.76 | K6: 2818.2 | L6: 0.145 | M6: 1.1 | N6: Mixed / simulated | O6: Simulated from ENERGY STAR multifamily EUI benchmark; not actual utility bills | P6: ENERGY STAR Portfolio Manager Data Explorer / U.S. National Median EUI table
A7: WI-MF-01 | B7: Riverbend Apartments | C7: Madison | D7: Dane | E7: WI | F7: Multifamily | G7: 2025-06 | H7: 104069 | I7: 1139 | J7: 15090 | K7: 1252.9 | L7: 0.145 | M7: 1.1 | N7: Mixed / simulated | O7: Simulated from ENERGY STAR multifamily EUI benchmark; not actual utility bills | P7: ENERGY STAR Portfolio Manager Data Explorer / U.S. National Median EUI table
A8: WI-MF-01 | B8: Riverbend Apartments | C8: Madison | D8: Dane | E8: WI | F8: Multifamily | G8: 2025-07 | H8: 118775 | I8: 683 | J8: 17222.38 | K8: 751.3 | L8: 0.145 | M8: 1.1 | N8: Mixed / simulated | O8: Simulated from ENERGY STAR multifamily EUI benchmark; not actual utility bills | P8: ENERGY STAR Portfolio Manager Data Explorer / U.S. National Median EUI table
A9: WI-MF-01 | B9: Riverbend Apartments | C9: Madison | D9: Dane | E9: WI | F9: Multifamily | G9: 2025-08 | H9: 118775 | I9: 683 | J9: 17222.38 | K9: 751.3 | L9: 0.145 | M9: 1.1 | N9: Mixed / simulated | O9: Simulated from ENERGY STAR multifamily EUI benchmark; not actual utility bills | P9: ENERGY STAR Portfolio Manager Data Explorer / U.S. National Median EUI table
A10: WI-MF-01 | B10: Riverbend Apartments | C10: Madison | D10: Dane | E10: WI | F10: Multifamily | G10: 2025-09 | H10: 98413 | I10: 1708 | J10: 14269.88 | K10: 1878.8 | L10: 0.145 | M10: 1.1 | N10: Mixed / simulated | O10: Simulated from ENERGY STAR multifamily EUI benchmark; not actual utility bills | P10: ENERGY STAR Portfolio Manager Data Explorer / U.S. National Median EUI table
A11: WI-MF-01 | B11: Riverbend Apartments | C11: Madison | D11: Dane | E11: WI | F11: Multifamily | G11: 2025-10 | H11: 88233 | I11: 3986 | J11: 12793.78 | K11: 4384.6 | L11: 0.145 | M11: 1.1 | N11: Mixed / simulated | O11: Simulated from ENERGY STAR multifamily EUI benchmark; not actual utility bills | P11: ENERGY STAR Portfolio Manager Data Explorer / U.S. National Median EUI table
A12: WI-MF-01 | B12: Riverbend Apartments | C12: Madison | D12: Dane | E12: WI | F12: Multifamily | G12: 2025-11 | H12: 82577 | I12: 6548 | J12: 11973.66 | K12: 7202.8 | L12: 0.145 | M12: 1.1 | N12: Mixed / simulated | O12: Simulated from ENERGY STAR multifamily EUI benchmark; not actual utility bills | P12: ENERGY STAR Portfolio Manager Data Explorer / U.S. National Median EUI table
A13: WI-MF-01 | B13: Riverbend Apartments | C13: Madison | D13: Dane | E13: WI | F13: Multifamily | G13: 2025-12 | H13: 83708 | I13: 8313 | J13: 12137.66 | K13: 9144.3 | L13: 0.145 | M13: 1.1 | N13: Mixed / simulated | O13: Simulated from ENERGY STAR multifamily EUI benchmark; not actual utility bills | P13: ENERGY STAR Portfolio Manager Data Explorer / U.S. National Median EUI table
... A121: WI-MF-10 | B121: Harbor Point Apartments | C121: Kenosha | D121: Kenosha | E121: WI | F121: Multifamily | G121: 2025-12 | H121: 82942 | I121: 9110 | J121: 12026.59 | K121: 10021 | L121: 0.145 | M121: 1.1 | N121: Mixed / simulated | O121: Simulated from ENERGY STAR multifamily EUI benchmark; not actual utility bills | P121: ENERGY STAR Portfolio Manager Data Explorer / U.S. National Median EUI table

Sheet 11_calc_energy_summary
A1: property_id | B1: property_name | C1: gross_floor_area_sqft | D1: units | E1: annual_electricity_kwh | F1: annual_natural_gas_therms | G1: annual_electricity_cost_usd | H1: annual_gas_cost_usd | I1: annual_total_energy_cost_usd | J1: electricity_kbtu | K1: natural_gas_kbtu | L1: total_energy_kbtu | M1: site_eui_kbtu_sqft | N1: electricity_intensity_kwh_sqft | O1: gas_intensity_therms_sqft | P1: energy_cost_per_unit | Q1: energy_cost_per_sqft | R1: months_with_energy_data | S1: energy_data_coverage_pct | T1: benchmark_site_eui | U1: eui_vs_benchmark | V1: energy_performance_flag | W1: energy_data_coverage_flag | X1: energy_priority_rank | Y1: recommended_energy_action
A2: WI-MF-01 | B2: =_xlfn.XLOOKUP(Energy_Summary_Template[[#This Row],[property_id]],Energy_Monthly[property_id],Energy_Monthly[property_name]) -> Riverbend Apartments | C2: =_xlfn.XLOOKUP(A2,'01_input_asset_master'!A$2:A$11,'01_input_asset_master'!H$2:H$11) -> 165000 | D2: =_xlfn.XLOOKUP(A2,'01_input_asset_master'!A$2:A$11,'01_input_asset_master'!I$2:I$11) -> 180 | E2: =SUMIFS('02_input_energy_monthly'!H:H,'02_input_energy_monthly'!A:A,A2) -> 1131188 | F2: =SUMIFS('02_input_energy_monthly'!I:I,'02_input_energy_monthly'!A:A,A2) -> 56939 | G2: =SUMIFS('02_input_energy_monthly'!J:J,'02_input_energy_monthly'!A:A,A2) -> 164022.23 | H2: =SUMIFS('02_input_energy_monthly'!K:K,'02_input_energy_monthly'!A:A,A2) -> 62632.9 | I2: =Energy_Summary_Template[[#This Row],[annual_gas_cost_usd]]+Energy_Summary_Template[[#This Row],[annual_electricity_cost_usd]] -> 226655.13 | J2: =E2*3.412 -> 3859613.5 | K2: =F2*100 -> 5693900 | L2: =Energy_Summary_Template[[#This Row],[electricity_kbtu]]+Energy_Summary_Template[[#This Row],[natural_gas_kbtu]] -> 9553513.5 | M2: =L2/C2 -> 57.900082 | N2: =E2/C2 -> 6.8556848 | O2: =F2/C2 -> 0.34508485 | P2: =I2/D2 -> 1259.1952 | Q2: =I2/C2 -> 1.3736675 | R2: =COUNTIFS('02_input_energy_monthly'!A:A,A2,'02_input_energy_monthly'!H:H,">0")+COUNTIFS('02_input_energy_monthly'!A:A,A2,'02_input_energy_monthly'!H:H,0,'02_input_energy_monthly'!I:I,">0") -> 12 | S2: =R2/12 -> 1 | T2: =59.6 -> 59.6 | U2: =M2-T2 -> -1.6999184 | V2: =IF(M2>70,"High Energy Use",IF(M2>59.6,"Above Benchmark","At/Below Benchmark")) -> At/Below Benchmark | W2: =IF(S2>=0.95,"Good",IF(S2>=0.75,"Needs Review","Weak")) -> Good | X2: =_xlfn.RANK.EQ(M2,$M$2:$M$11,0) -> 5 | Y2: =IF(M2>65,"Energy audit + heating system review", IF(M2>59.6,"Monitor + targeted efficiency upgrades", "Maintain performance")) -> Maintain performance
A3: WI-MF-02 | B3: =_xlfn.XLOOKUP(Energy_Summary_Template[[#This Row],[property_id]],Energy_Monthly[property_id],Energy_Monthly[property_name]) -> Lakeview Terrace | C3: =_xlfn.XLOOKUP(A3,'01_input_asset_master'!A$2:A$11,'01_input_asset_master'!H$2:H$11) -> 220000 | D3: =_xlfn.XLOOKUP(A3,'01_input_asset_master'!A$2:A$11,'01_input_asset_master'!I$2:I$11) -> 240 | E3: =SUMIFS('02_input_energy_monthly'!H:H,'02_input_energy_monthly'!A:A,A3) -> 1622015 | F3: =SUMIFS('02_input_energy_monthly'!I:I,'02_input_energy_monthly'!A:A,A3) -> 90298 | G3: =SUMIFS('02_input_energy_monthly'!J:J,'02_input_energy_monthly'!A:A,A3) -> 235192.16 | H3: =SUMIFS('02_input_energy_monthly'!K:K,'02_input_energy_monthly'!A:A,A3) -> 99327.8 | I3: =Energy_Summary_Template[[#This Row],[annual_gas_cost_usd]]+Energy_Summary_Template[[#This Row],[annual_electricity_cost_usd]] -> 334519.96 | J3: =E3*3.412 -> 5534315.2 | K3: =F3*100 -> 9029800 | L3: =Energy_Summary_Template[[#This Row],[electricity_kbtu]]+Energy_Summary_Template[[#This Row],[natural_gas_kbtu]] -> 14564115 | M3: =L3/C3 -> 66.200524 | N3: =E3/C3 -> 7.3727955 | O3: =F3/C3 -> 0.41044545 | P3: =I3/D3 -> 1393.8332 | Q3: =I3/C3 -> 1.5205453 | R3: =COUNTIFS('02_input_energy_monthly'!A:A,A3,'02_input_energy_monthly'!H:H,">0")+COUNTIFS('02_input_energy_monthly'!A:A,A3,'02_input_energy_monthly'!H:H,0,'02_input_energy_monthly'!I:I,">0") -> 12 | S3: =R3/12 -> 1 | T3: =59.6 -> 59.6 | U3: =M3-T3 -> 6.6005235 | V3: =IF(M3>70,"High Energy Use",IF(M3>59.6,"Above Benchmark","At/Below Benchmark")) -> Above Benchmark | W3: =IF(S3>=0.95,"Good",IF(S3>=0.75,"Needs Review","Weak")) -> Good | X3: =_xlfn.RANK.EQ(M3,$M$2:$M$11,0) -> 2 | Y3: =IF(M3>65,"Energy audit + heating system review", IF(M3>59.6,"Monitor + targeted efficiency upgrades", "Maintain performance")) -> Energy audit + heating system review
A4: WI-MF-03 | B4: =_xlfn.XLOOKUP(Energy_Summary_Template[[#This Row],[property_id]],Energy_Monthly[property_id],Energy_Monthly[property_name]) -> Northside Commons | C4: =_xlfn.XLOOKUP(A4,'01_input_asset_master'!A$2:A$11,'01_input_asset_master'!H$2:H$11) -> 145000 | D4: =_xlfn.XLOOKUP(A4,'01_input_asset_master'!A$2:A$11,'01_input_asset_master'!I$2:I$11) -> 160 | E4: =SUMIFS('02_input_energy_monthly'!H:H,'02_input_energy_monthly'!A:A,A4) -> 980726 | F4: =SUMIFS('02_input_energy_monthly'!I:I,'02_input_energy_monthly'!A:A,A4) -> 45270 | G4: =SUMIFS('02_input_energy_monthly'!J:J,'02_input_energy_monthly'!A:A,A4) -> 142205.25 | H4: =SUMIFS('02_input_energy_monthly'!K:K,'02_input_energy_monthly'!A:A,A4) -> 49797 | I4: =Energy_Summary_Template[[#This Row],[annual_gas_cost_usd]]+Energy_Summary_Template[[#This Row],[annual_electricity_cost_usd]] -> 192002.25 | J4: =E4*3.412 -> 3346237.1 | K4: =F4*100 -> 4527000 | L4: =Energy_Summary_Template[[#This Row],[electricity_kbtu]]+Energy_Summary_Template[[#This Row],[natural_gas_kbtu]] -> 7873237.1 | M4: =L4/C4 -> 54.298187 | N4: =E4/C4 -> 6.7636276 | O4: =F4/C4 -> 0.3122069 | P4: =I4/D4 -> 1200.0141 | Q4: =I4/C4 -> 1.3241534 | R4: =COUNTIFS('02_input_energy_monthly'!A:A,A4,'02_input_energy_monthly'!H:H,">0")+COUNTIFS('02_input_energy_monthly'!A:A,A4,'02_input_energy_monthly'!H:H,0,'02_input_energy_monthly'!I:I,">0") -> 12 | S4: =R4/12 -> 1 | T4: =59.6 -> 59.6 | U4: =M4-T4 -> -5.301813 | V4: =IF(M4>70,"High Energy Use",IF(M4>59.6,"Above Benchmark","At/Below Benchmark")) -> At/Below Benchmark | W4: =IF(S4>=0.95,"Good",IF(S4>=0.75,"Needs Review","Weak")) -> Good | X4: =_xlfn.RANK.EQ(M4,$M$2:$M$11,0) -> 7 | Y4: =IF(M4>65,"Energy audit + heating system review", IF(M4>59.6,"Monitor + targeted efficiency upgrades", "Maintain performance")) -> Maintain performance
A5: WI-MF-04 | B5: =_xlfn.XLOOKUP(Energy_Summary_Template[[#This Row],[property_id]],Energy_Monthly[property_id],Energy_Monthly[property_name]) -> Badger Ridge Homes | C5: =_xlfn.XLOOKUP(A5,'01_input_asset_master'!A$2:A$11,'01_input_asset_master'!H$2:H$11) -> 120000 | D5: =_xlfn.XLOOKUP(A5,'01_input_asset_master'!A$2:A$11,'01_input_asset_master'!I$2:I$11) -> 130 | E5: =SUMIFS('02_input_energy_monthly'!H:H,'02_input_energy_monthly'!A:A,A5) -> 837617 | F5: =SUMIFS('02_input_energy_monthly'!I:I,'02_input_energy_monthly'!A:A,A5) -> 45461 | G5: =SUMIFS('02_input_energy_monthly'!J:J,'02_input_energy_monthly'!A:A,A5) -> 121454.46 | H5: =SUMIFS('02_input_energy_monthly'!K:K,'02_input_energy_monthly'!A:A,A5) -> 50007.1 | I5: =Energy_Summary_Template[[#This Row],[annual_gas_cost_usd]]+Energy_Summary_Template[[#This Row],[annual_electricity_cost_usd]] -> 171461.56 | J5: =E5*3.412 -> 2857949.2 | K5: =F5*100 -> 4546100 | L5: =Energy_Summary_Template[[#This Row],[electricity_kbtu]]+Energy_Summary_Template[[#This Row],[natural_gas_kbtu]] -> 7404049.2 | M5: =L5/C5 -> 61.70041 | N5: =E5/C5 -> 6.9801417 | O5: =F5/C5 -> 0.37884167 | P5: =I5/D5 -> 1318.9351 | Q5: =I5/C5 -> 1.4288463 | R5: =COUNTIFS('02_input_energy_monthly'!A:A,A5,'02_input_energy_monthly'!H:H,">0")+COUNTIFS('02_input_energy_monthly'!A:A,A5,'02_input_energy_monthly'!H:H,0,'02_input_energy_monthly'!I:I,">0") -> 12 | S5: =R5/12 -> 1 | T5: =59.6 -> 59.6 | U5: =M5-T5 -> 2.10041 | V5: =IF(M5>70,"High Energy Use",IF(M5>59.6,"Above Benchmark","At/Below Benchmark")) -> Above Benchmark | W5: =IF(S5>=0.95,"Good",IF(S5>=0.75,"Needs Review","Weak")) -> Good | X5: =_xlfn.RANK.EQ(M5,$M$2:$M$11,0) -> 4 | Y5: =IF(M5>65,"Energy audit + heating system review", IF(M5>59.6,"Monitor + targeted efficiency upgrades", "Maintain performance")) -> Monitor + targeted efficiency upgrades
A6: WI-MF-05 | B6: =_xlfn.XLOOKUP(Energy_Summary_Template[[#This Row],[property_id]],Energy_Monthly[property_id],Energy_Monthly[property_name]) -> Oak Street Lofts | C6: =_xlfn.XLOOKUP(A6,'01_input_asset_master'!A$2:A$11,'01_input_asset_master'!H$2:H$11) -> 98000 | D6: =_xlfn.XLOOKUP(A6,'01_input_asset_master'!A$2:A$11,'01_input_asset_master'!I$2:I$11) -> 105 | E6: =SUMIFS('02_input_energy_monthly'!H:H,'02_input_energy_monthly'!A:A,A6) -> 642364 | F6: =SUMIFS('02_input_energy_monthly'!I:I,'02_input_energy_monthly'!A:A,A6) -> 25318 | G6: =SUMIFS('02_input_energy_monthly'!J:J,'02_input_energy_monthly'!A:A,A6) -> 93142.75 | H6: =SUMIFS('02_input_energy_monthly'!K:K,'02_input_energy_monthly'!A:A,A6) -> 27849.8 | I6: =Energy_Summary_Template[[#This Row],[annual_gas_cost_usd]]+Energy_Summary_Template[[#This Row],[annual_electricity_cost_usd]] -> 120992.55 | J6: =E6*3.412 -> 2191746 | K6: =F6*100 -> 2531800 | L6: =Energy_Summary_Template[[#This Row],[electricity_kbtu]]+Energy_Summary_Template[[#This Row],[natural_gas_kbtu]] -> 4723546 | M6: =L6/C6 -> 48.199449 | N6: =E6/C6 -> 6.5547347 | O6: =F6/C6 -> 0.25834694 | P6: =I6/D6 -> 1152.31 | Q6: =I6/C6 -> 1.2346179 | R6: =COUNTIFS('02_input_energy_monthly'!A:A,A6,'02_input_energy_monthly'!H:H,">0")+COUNTIFS('02_input_energy_monthly'!A:A,A6,'02_input_energy_monthly'!H:H,0,'02_input_energy_monthly'!I:I,">0") -> 12 | S6: =R6/12 -> 1 | T6: =59.6 -> 59.6 | U6: =M6-T6 -> -11.400551 | V6: =IF(M6>70,"High Energy Use",IF(M6>59.6,"Above Benchmark","At/Below Benchmark")) -> At/Below Benchmark | W6: =IF(S6>=0.95,"Good",IF(S6>=0.75,"Needs Review","Weak")) -> Good | X6: =_xlfn.RANK.EQ(M6,$M$2:$M$11,0) -> 9 | Y6: =IF(M6>65,"Energy audit + heating system review", IF(M6>59.6,"Monitor + targeted efficiency upgrades", "Maintain performance")) -> Maintain performance
A7: WI-MF-06 | B7: =_xlfn.XLOOKUP(Energy_Summary_Template[[#This Row],[property_id]],Energy_Monthly[property_id],Energy_Monthly[property_name]) -> South Park Apartments | C7: =_xlfn.XLOOKUP(A7,'01_input_asset_master'!A$2:A$11,'01_input_asset_master'!H$2:H$11) -> 185000 | D7: =_xlfn.XLOOKUP(A7,'01_input_asset_master'!A$2:A$11,'01_input_asset_master'!I$2:I$11) -> 210 | E7: =SUMIFS('02_input_energy_monthly'!H:H,'02_input_energy_monthly'!A:A,A7) -> 1394876 | F7: =SUMIFS('02_input_energy_monthly'!I:I,'02_input_energy_monthly'!A:A,A7) -> 77653 | G7: =SUMIFS('02_input_energy_monthly'!J:J,'02_input_energy_monthly'!A:A,A7) -> 202257.01 | H7: =SUMIFS('02_input_energy_monthly'!K:K,'02_input_energy_monthly'!A:A,A7) -> 85418.3 | I7: =Energy_Summary_Template[[#This Row],[annual_gas_cost_usd]]+Energy_Summary_Template[[#This Row],[annual_electricity_cost_usd]] -> 287675.31 | J7: =E7*3.412 -> 4759316.9 | K7: =F7*100 -> 7765300 | L7: =Energy_Summary_Template[[#This Row],[electricity_kbtu]]+Energy_Summary_Template[[#This Row],[natural_gas_kbtu]] -> 12524617 | M7: =L7/C7 -> 67.700632 | N7: =E7/C7 -> 7.5398703 | O7: =F7/C7 -> 0.41974595 | P7: =I7/D7 -> 1369.8824 | Q7: =I7/C7 -> 1.5550017 | R7: =COUNTIFS('02_input_energy_monthly'!A:A,A7,'02_input_energy_monthly'!H:H,">0")+COUNTIFS('02_input_energy_monthly'!A:A,A7,'02_input_energy_monthly'!H:H,0,'02_input_energy_monthly'!I:I,">0") -> 12 | S7: =R7/12 -> 1 | T7: =59.6 -> 59.6 | U7: =M7-T7 -> 8.100632 | V7: =IF(M7>70,"High Energy Use",IF(M7>59.6,"Above Benchmark","At/Below Benchmark")) -> Above Benchmark | W7: =IF(S7>=0.95,"Good",IF(S7>=0.75,"Needs Review","Weak")) -> Good | X7: =_xlfn.RANK.EQ(M7,$M$2:$M$11,0) -> 1 | Y7: =IF(M7>65,"Energy audit + heating system review", IF(M7>59.6,"Monitor + targeted efficiency upgrades", "Maintain performance")) -> Energy audit + heating system review
A8: WI-MF-07 | B8: =_xlfn.XLOOKUP(Energy_Summary_Template[[#This Row],[property_id]],Energy_Monthly[property_id],Energy_Monthly[property_name]) -> Fox River Flats | C8: =_xlfn.XLOOKUP(A8,'01_input_asset_master'!A$2:A$11,'01_input_asset_master'!H$2:H$11) -> 135000 | D8: =_xlfn.XLOOKUP(A8,'01_input_asset_master'!A$2:A$11,'01_input_asset_master'!I$2:I$11) -> 150 | E8: =SUMIFS('02_input_energy_monthly'!H:H,'02_input_energy_monthly'!A:A,A8) -> 907943 | F8: =SUMIFS('02_input_energy_monthly'!I:I,'02_input_energy_monthly'!A:A,A8) -> 38951 | G8: =SUMIFS('02_input_energy_monthly'!J:J,'02_input_energy_monthly'!A:A,A8) -> 131651.71 | H8: =SUMIFS('02_input_energy_monthly'!K:K,'02_input_energy_monthly'!A:A,A8) -> 42846.1 | I8: =Energy_Summary_Template[[#This Row],[annual_gas_cost_usd]]+Energy_Summary_Template[[#This Row],[annual_electricity_cost_usd]] -> 174497.81 | J8: =E8*3.412 -> 3097901.5 | K8: =F8*100 -> 3895100 | L8: =Energy_Summary_Template[[#This Row],[electricity_kbtu]]+Energy_Summary_Template[[#This Row],[natural_gas_kbtu]] -> 6993001.5 | M8: =L8/C8 -> 51.800011 | N8: =E8/C8 -> 6.7255037 | O8: =F8/C8 -> 0.28852593 | P8: =I8/D8 -> 1163.3187 | Q8: =I8/C8 -> 1.2925764 | R8: =COUNTIFS('02_input_energy_monthly'!A:A,A8,'02_input_energy_monthly'!H:H,">0")+COUNTIFS('02_input_energy_monthly'!A:A,A8,'02_input_energy_monthly'!H:H,0,'02_input_energy_monthly'!I:I,">0") -> 12 | S8: =R8/12 -> 1 | T8: =59.6 -> 59.6 | U8: =M8-T8 -> -7.7999888 | V8: =IF(M8>70,"High Energy Use",IF(M8>59.6,"Above Benchmark","At/Below Benchmark")) -> At/Below Benchmark | W8: =IF(S8>=0.95,"Good",IF(S8>=0.75,"Needs Review","Weak")) -> Good | X8: =_xlfn.RANK.EQ(M8,$M$2:$M$11,0) -> 8 | Y8: =IF(M8>65,"Energy audit + heating system review", IF(M8>59.6,"Monitor + targeted efficiency upgrades", "Maintain performance")) -> Maintain performance
A9: WI-MF-08 | B9: =_xlfn.XLOOKUP(Energy_Summary_Template[[#This Row],[property_id]],Energy_Monthly[property_id],Energy_Monthly[property_name]) -> Prairie View Residences | C9: =_xlfn.XLOOKUP(A9,'01_input_asset_master'!A$2:A$11,'01_input_asset_master'!H$2:H$11) -> 110000 | D9: =_xlfn.XLOOKUP(A9,'01_input_asset_master'!A$2:A$11,'01_input_asset_master'!I$2:I$11) -> 120 | E9: =SUMIFS('02_input_energy_monthly'!H:H,'02_input_energy_monthly'!A:A,A9) -> 760039 | F9: =SUMIFS('02_input_energy_monthly'!I:I,'02_input_energy_monthly'!A:A,A9) -> 37317 | G9: =SUMIFS('02_input_energy_monthly'!J:J,'02_input_energy_monthly'!A:A,A9) -> 110205.61 | H9: =SUMIFS('02_input_energy_monthly'!K:K,'02_input_energy_monthly'!A:A,A9) -> 41048.7 | I9: =Energy_Summary_Template[[#This Row],[annual_gas_cost_usd]]+Energy_Summary_Template[[#This Row],[annual_electricity_cost_usd]] -> 151254.31 | J9: =E9*3.412 -> 2593253.1 | K9: =F9*100 -> 3731700 | L9: =Energy_Summary_Template[[#This Row],[electricity_kbtu]]+Energy_Summary_Template[[#This Row],[natural_gas_kbtu]] -> 6324953.1 | M9: =L9/C9 -> 57.499573 | N9: =E9/C9 -> 6.9094455 | O9: =F9/C9 -> 0.33924545 | P9: =I9/D9 -> 1260.4526 | Q9: =I9/C9 -> 1.3750392 | R9: =COUNTIFS('02_input_energy_monthly'!A:A,A9,'02_input_energy_monthly'!H:H,">0")+COUNTIFS('02_input_energy_monthly'!A:A,A9,'02_input_energy_monthly'!H:H,0,'02_input_energy_monthly'!I:I,">0") -> 12 | S9: =R9/12 -> 1 | T9: =59.6 -> 59.6 | U9: =M9-T9 -> -2.1004267 | V9: =IF(M9>70,"High Energy Use",IF(M9>59.6,"Above Benchmark","At/Below Benchmark")) -> At/Below Benchmark | W9: =IF(S9>=0.95,"Good",IF(S9>=0.75,"Needs Review","Weak")) -> Good | X9: =_xlfn.RANK.EQ(M9,$M$2:$M$11,0) -> 6 | Y9: =IF(M9>65,"Energy audit + heating system review", IF(M9>59.6,"Monitor + targeted efficiency upgrades", "Maintain performance")) -> Maintain performance
A10: WI-MF-09 | B10: =_xlfn.XLOOKUP(Energy_Summary_Template[[#This Row],[property_id]],Energy_Monthly[property_id],Energy_Monthly[property_name]) -> Capitol Square Homes | C10: =_xlfn.XLOOKUP(A10,'01_input_asset_master'!A$2:A$11,'01_input_asset_master'!H$2:H$11) -> 175000 | D10: =_xlfn.XLOOKUP(A10,'01_input_asset_master'!A$2:A$11,'01_input_asset_master'!I$2:I$11) -> 190 | E10: =SUMIFS('02_input_energy_monthly'!H:H,'02_input_energy_monthly'!A:A,A10) -> 1169146 | F10: =SUMIFS('02_input_energy_monthly'!I:I,'02_input_energy_monthly'!A:A,A10) -> 42358 | G10: =SUMIFS('02_input_energy_monthly'!J:J,'02_input_energy_monthly'!A:A,A10) -> 169526.15 | H10: =SUMIFS('02_input_energy_monthly'!K:K,'02_input_energy_monthly'!A:A,A10) -> 46593.8 | I10: =Energy_Summary_Template[[#This Row],[annual_gas_cost_usd]]+Energy_Summary_Template[[#This Row],[annual_electricity_cost_usd]] -> 216119.95 | J10: =E10*3.412 -> 3989126.2 | K10: =F10*100 -> 4235800 | L10: =Energy_Summary_Template[[#This Row],[electricity_kbtu]]+Energy_Summary_Template[[#This Row],[natural_gas_kbtu]] -> 8224926.2 | M10: =L10/C10 -> 46.999578 | N10: =E10/C10 -> 6.6808343 | O10: =F10/C10 -> 0.24204571 | P10: =I10/D10 -> 1137.4734 | Q10: =I10/C10 -> 1.2349711 | R10: =COUNTIFS('02_input_energy_monthly'!A:A,A10,'02_input_energy_monthly'!H:H,">0")+COUNTIFS('02_input_energy_monthly'!A:A,A10,'02_input_energy_monthly'!H:H,0,'02_input_energy_monthly'!I:I,">0") -> 12 | S10: =R10/12 -> 1 | T10: =59.6 -> 59.6 | U10: =M10-T10 -> -12.600422 | V10: =IF(M10>70,"High Energy Use",IF(M10>59.6,"Above Benchmark","At/Below Benchmark")) -> At/Below Benchmark | W10: =IF(S10>=0.95,"Good",IF(S10>=0.75,"Needs Review","Weak")) -> Good | X10: =_xlfn.RANK.EQ(M10,$M$2:$M$11,0) -> 10 | Y10: =IF(M10>65,"Energy audit + heating system review", IF(M10>59.6,"Monitor + targeted efficiency upgrades", "Maintain performance")) -> Maintain performance
A11: WI-MF-10 | B11: =_xlfn.XLOOKUP(Energy_Summary_Template[[#This Row],[property_id]],Energy_Monthly[property_id],Energy_Monthly[property_name]) -> Harbor Point Apartments | C11: =_xlfn.XLOOKUP(A11,'01_input_asset_master'!A$2:A$11,'01_input_asset_master'!H$2:H$11) -> 160000 | D11: =_xlfn.XLOOKUP(A11,'01_input_asset_master'!A$2:A$11,'01_input_asset_master'!I$2:I$11) -> 175 | E11: =SUMIFS('02_input_energy_monthly'!H:H,'02_input_energy_monthly'!A:A,A11) -> 1120844 | F11: =SUMIFS('02_input_energy_monthly'!I:I,'02_input_energy_monthly'!A:A,A11) -> 62399 | G11: =SUMIFS('02_input_energy_monthly'!J:J,'02_input_energy_monthly'!A:A,A11) -> 162522.35 | H11: =SUMIFS('02_input_energy_monthly'!K:K,'02_input_energy_monthly'!A:A,A11) -> 68638.9 | I11: =Energy_Summary_Template[[#This Row],[annual_gas_cost_usd]]+Energy_Summary_Template[[#This Row],[annual_electricity_cost_usd]] -> 231161.25 | J11: =E11*3.412 -> 3824319.7 | K11: =F11*100 -> 6239900 | L11: =Energy_Summary_Template[[#This Row],[electricity_kbtu]]+Energy_Summary_Template[[#This Row],[natural_gas_kbtu]] -> 10064220 | M11: =L11/C11 -> 62.901373 | N11: =E11/C11 -> 7.005275 | O11: =F11/C11 -> 0.38999375 | P11: =I11/D11 -> 1320.9214 | Q11: =I11/C11 -> 1.4447578 | R11: =COUNTIFS('02_input_energy_monthly'!A:A,A11,'02_input_energy_monthly'!H:H,">0")+COUNTIFS('02_input_energy_monthly'!A:A,A11,'02_input_energy_monthly'!H:H,0,'02_input_energy_monthly'!I:I,">0") -> 12 | S11: =R11/12 -> 1 | T11: =59.6 -> 59.6 | U11: =M11-T11 -> 3.3013733 | V11: =IF(M11>70,"High Energy Use",IF(M11>59.6,"Above Benchmark","At/Below Benchmark")) -> Above Benchmark | W11: =IF(S11>=0.95,"Good",IF(S11>=0.75,"Needs Review","Weak")) -> Good | X11: =_xlfn.RANK.EQ(M11,$M$2:$M$11,0) -> 3 | Y11: =IF(M11>65,"Energy audit + heating system review", IF(M11>59.6,"Monitor + targeted efficiency upgrades", "Maintain performance")) -> Monitor + targeted efficiency upgrades

Sheet 03_input_water_monthly
A1: property_id | B1: property_name | C1: city | D1: county | E1: month | F1: water_gallons | G1: water_cost_usd | H1: sewer_cost_usd | I1: irrigation_included | J1: owner_or_tenant_paid | K1: data_quality | L1: notes
A2: WI-MF-01 | B2: Riverbend Apartments | C2: Madison | D2: Dane | E2: 45658 | F2: 803652 | G2: 3544.11 | H2: 4303.56 | I2: No | J2: Owner/Paid by property | K2: Actual | L2: Simulated using EPA 82 gal/person/day reference; replace with water bills/Portfolio Manager export for real diligence.
A3: WI-MF-01 | B3: Riverbend Apartments | C3: Madison | D3: Dane | E3: 45689 | F3: 664746 | G3: 2931.53 | H3: 3559.71 | I3: No | J3: Owner/Paid by property | K3: Actual | L3: Simulated using EPA 82 gal/person/day reference; replace with water bills/Portfolio Manager export for real diligence.
A4: WI-MF-01 | B4: Riverbend Apartments | C4: Madison | D4: Dane | E4: 45717 | F4: 808895 | G4: 3567.23 | H4: 4331.63 | I4: No | J4: Owner/Paid by property | K4: Actual | L4: Simulated using EPA 82 gal/person/day reference; replace with water bills/Portfolio Manager export for real diligence.
A5: WI-MF-01 | B5: Riverbend Apartments | C5: Madison | D5: Dane | E5: 45748 | F5: 804546 | G5: 3548.05 | H5: 4308.34 | I5: No | J5: Owner/Paid by property | K5: Actual | L5: Simulated using EPA 82 gal/person/day reference; replace with water bills/Portfolio Manager export for real diligence.
A6: WI-MF-01 | B6: Riverbend Apartments | C6: Madison | D6: Dane | E6: 45778 | F6: 923382 | G6: 4072.12 | H6: 4944.71 | I6: Yes | J6: Owner/Paid by property | K6: Actual | L6: Simulated using EPA 82 gal/person/day reference; replace with water bills/Portfolio Manager export for real diligence.
A7: WI-MF-01 | B7: Riverbend Apartments | C7: Madison | D7: Dane | E7: 45809 | F7: 1018532 | G7: 4491.73 | H7: 5454.24 | I7: Yes | J7: Owner/Paid by property | K7: Actual | L7: Simulated using EPA 82 gal/person/day reference; replace with water bills/Portfolio Manager export for real diligence.
A8: WI-MF-01 | B8: Riverbend Apartments | C8: Madison | D8: Dane | E8: 45839 | F8: 1133183 | G8: 4997.34 | H8: 6068.2 | I8: Yes | J8: Owner/Paid by property | K8: Actual | L8: Simulated using EPA 82 gal/person/day reference; replace with water bills/Portfolio Manager export for real diligence.
A9: WI-MF-01 | B9: Riverbend Apartments | C9: Madison | D9: Dane | E9: 45870 | F9: 1053458 | G9: 4645.75 | H9: 5641.27 | I9: Yes | J9: Owner/Paid by property | K9: Actual | L9: Simulated using EPA 82 gal/person/day reference; replace with water bills/Portfolio Manager export for real diligence.
A10: WI-MF-01 | B10: Riverbend Apartments | C10: Madison | D10: Dane | E10: 45901 | F10: 899219 | G10: 3965.55 | H10: 4815.32 | I10: Yes | J10: Owner/Paid by property | K10: Actual | L10: Simulated using EPA 82 gal/person/day reference; replace with water bills/Portfolio Manager export for real diligence.
A11: WI-MF-01 | B11: Riverbend Apartments | C11: Madison | D11: Dane | E11: 45931 | F11: 836618 | G11: 3689.49 | H11: 4480.09 | I11: No | J11: Owner/Paid by property | K11: Actual | L11: Simulated using EPA 82 gal/person/day reference; replace with water bills/Portfolio Manager export for real diligence.
A12: WI-MF-01 | B12: Riverbend Apartments | C12: Madison | D12: Dane | E12: 45962 | F12: 771455 | G12: 3402.12 | H12: 4131.14 | I12: No | J12: Owner/Paid by property | K12: Actual | L12: Simulated using EPA 82 gal/person/day reference; replace with water bills/Portfolio Manager export for real diligence.
A13: WI-MF-01 | B13: Riverbend Apartments | C13: Madison | D13: Dane | E13: 45992 | F13: 804837 | G13: 3549.33 | H13: 4309.9 | I13: No | J13: Owner/Paid by property | K13: Actual | L13: Simulated using EPA 82 gal/person/day reference; replace with water bills/Portfolio Manager export for real diligence.
... A121: WI-MF-10 | B121: Harbor Point Apartments | C121: Kenosha | D121: Kenosha | E121: 45992 | F121: 873848 | G121: 3927.07 | H121: 4768.59 | I121: No | J121: Owner/Paid by property | K121: Actual | L121: Simulated using EPA 82 gal/person/day reference; replace with water bills/Portfolio Manager export for real diligence.

Sheet 12_calc_water_summary
A1: property_id | B1: property_name | C1: gross_floor_area_sqft | D1: unit | E1: annual_water_gallons | F1: annual_water_cost_usd | G1: annual_sewer_cost_usd | H1: annual_total_water_sewer_cost_usd | I1: water_intensity_gal_sqft | J1: water_per_unit_gal | K1: water_cost_per_unit | L1: water_cost_per_sqft | M1: months_with_water_data | N1: water_data_coverage_pct | O1: water_performance_flag | P1: water_cost_flag | Q1: recommended_water_action | R1: water_cost_priority_rank | S1: water_intensity_rank | T1: combined_water_priority_score | U1: combined_water_priority_rank
A2: WI-MF-01 | B2: =_xlfn.XLOOKUP(A2,'01_input_asset_master'!A$2:A$11,'01_input_asset_master'!B$2:B$11) -> Riverbend Apartments | C2: =_xlfn.XLOOKUP(A2,'01_input_asset_master'!A$2:A$11,'01_input_asset_master'!H$2:H$11) -> 165000 | D2: =_xlfn.XLOOKUP(A2,'01_input_asset_master'!A$2:A$11,'01_input_asset_master'!I$2:I$11) -> 180 | E2: =SUMIFS('03_input_water_monthly'!G:G,'03_input_water_monthly'!A:A,A2) -> 46404.35 | F2: =SUMIFS('03_input_water_monthly'!H:H,'03_input_water_monthly'!A:A,A2) -> 56348.11 | G2: =SUMIFS('03_input_water_monthly'!H:H,'03_input_water_monthly'!A:A,A2) -> 56348.11 | H2: =F2+G2 -> 112696.22 | I2: =E2/C2 -> 0.28123848 | J2: =E2/D2 -> 257.80194 | K2: =H2/D2 -> 626.09011 | L2: =H2/C2 -> 0.68300739 | M2: =COUNTIFS('03_input_water_monthly'!A:A,A2,'03_input_water_monthly'!E:E,">0") -> 12 | N2: =M2/12 -> 1 | O2: =IF(J2>75000,"High Water Use",IF(J2>55000,"Moderate","Efficient/Low")) -> Efficient/Low | P2: =IF(K2>700,"High Cost",IF(K2>500,"Moderate Cost","Low Cost")) -> Moderate Cost | Q2: =IF(O2="High Water Use","Leak detection + low-flow fixtures + irrigation review",IF(O2="Moderate","Monitor usage + fixture review","Maintain performance")) -> Maintain performance | R2: =_xlfn.RANK.EQ(K2,$K$2:$K$11,0) -> 4 | S2: =_xlfn.RANK.EQ(I2,$I$2:$I$11,0) -> 4 | T2: =_xlfn.RANK.EQ(J2,$J$2:$J$11,0)+_xlfn.RANK.EQ(K2,$K$2:$K$11,0) -> 8 | U2: =_xlfn.RANK.EQ(J2,$J$2:$J$11,0)+_xlfn.RANK.EQ(K2,$K$2:$K$11,0) -> 8 | Y2: Water performance analysis shows which multifamily properties have the highest annual water use and water/sewer cost after normalizing by units and square footage. The most useful KPI is water gallons per unit because it reflects resident-level and operational water demand. Properties with high water use per unit and high water/sewer cost per unit should be prioritized for leak detection, low-flow fixtures, plumbing review, and irrigation checks.
A3: WI-MF-02 | B3: =_xlfn.XLOOKUP(A3,'01_input_asset_master'!A$2:A$11,'01_input_asset_master'!B$2:B$11) -> Lakeview Terrace | C3: =_xlfn.XLOOKUP(A3,'01_input_asset_master'!A$2:A$11,'01_input_asset_master'!H$2:H$11) -> 220000 | D3: =_xlfn.XLOOKUP(A3,'01_input_asset_master'!A$2:A$11,'01_input_asset_master'!I$2:I$11) -> 240 | E3: =SUMIFS('03_input_water_monthly'!G:G,'03_input_water_monthly'!A:A,A3) -> 79558.5 | F3: =SUMIFS('03_input_water_monthly'!H:H,'03_input_water_monthly'!A:A,A3) -> 96606.74 | G3: =SUMIFS('03_input_water_monthly'!H:H,'03_input_water_monthly'!A:A,A3) -> 96606.74 | H3: =F3+G3 -> 193213.48 | I3: =E3/C3 -> 0.36162955 | J3: =E3/D3 -> 331.49375 | K3: =H3/D3 -> 805.05617 | L3: =H3/C3 -> 0.87824309 | M3: =COUNTIFS('03_input_water_monthly'!A:A,A3,'03_input_water_monthly'!E:E,">0") -> 12 | N3: =M3/12 -> 1 | O3: =IF(J3>75000,"High Water Use",IF(J3>55000,"Moderate","Efficient/Low")) -> Efficient/Low | P3: =IF(K3>700,"High Cost",IF(K3>500,"Moderate Cost","Low Cost")) -> High Cost | Q3: =IF(O3="High Water Use","Leak detection + low-flow fixtures + irrigation review",IF(O3="Moderate","Monitor usage + fixture review","Maintain performance")) -> Maintain performance | R3: =_xlfn.RANK.EQ(K3,$K$2:$K$11,0) -> 1 | S3: =_xlfn.RANK.EQ(I3,$I$2:$I$11,0) -> 1 | T3: =_xlfn.RANK.EQ(J3,$J$2:$J$11,0)+_xlfn.RANK.EQ(K3,$K$2:$K$11,0) -> 2 | U3: =_xlfn.RANK.EQ(J3,$J$2:$J$11,0)+_xlfn.RANK.EQ(K3,$K$2:$K$11,0) -> 2
A4: WI-MF-03 | B4: =_xlfn.XLOOKUP(A4,'01_input_asset_master'!A$2:A$11,'01_input_asset_master'!B$2:B$11) -> Northside Commons | C4: =_xlfn.XLOOKUP(A4,'01_input_asset_master'!A$2:A$11,'01_input_asset_master'!H$2:H$11) -> 145000 | D4: =_xlfn.XLOOKUP(A4,'01_input_asset_master'!A$2:A$11,'01_input_asset_master'!I$2:I$11) -> 160 | E4: =SUMIFS('03_input_water_monthly'!G:G,'03_input_water_monthly'!A:A,A4) -> 37799.44 | F4: =SUMIFS('03_input_water_monthly'!H:H,'03_input_water_monthly'!A:A,A4) -> 45899.32 | G4: =SUMIFS('03_input_water_monthly'!H:H,'03_input_water_monthly'!A:A,A4) -> 45899.32 | H4: =F4+G4 -> 91798.64 | I4: =E4/C4 -> 0.26068579 | J4: =E4/D4 -> 236.2465 | K4: =H4/D4 -> 573.7415 | L4: =H4/C4 -> 0.63309407 | M4: =COUNTIFS('03_input_water_monthly'!A:A,A4,'03_input_water_monthly'!E:E,">0") -> 12 | N4: =M4/12 -> 1 | O4: =IF(J4>75000,"High Water Use",IF(J4>55000,"Moderate","Efficient/Low")) -> Efficient/Low | P4: =IF(K4>700,"High Cost",IF(K4>500,"Moderate Cost","Low Cost")) -> Moderate Cost | Q4: =IF(O4="High Water Use","Leak detection + low-flow fixtures + irrigation review",IF(O4="Moderate","Monitor usage + fixture review","Maintain performance")) -> Maintain performance | R4: =_xlfn.RANK.EQ(K4,$K$2:$K$11,0) -> 6 | S4: =_xlfn.RANK.EQ(I4,$I$2:$I$11,0) -> 6 | T4: =_xlfn.RANK.EQ(J4,$J$2:$J$11,0)+_xlfn.RANK.EQ(K4,$K$2:$K$11,0) -> 12 | U4: =_xlfn.RANK.EQ(J4,$J$2:$J$11,0)+_xlfn.RANK.EQ(K4,$K$2:$K$11,0) -> 12
A5: WI-MF-04 | B5: =_xlfn.XLOOKUP(A5,'01_input_asset_master'!A$2:A$11,'01_input_asset_master'!B$2:B$11) -> Badger Ridge Homes | C5: =_xlfn.XLOOKUP(A5,'01_input_asset_master'!A$2:A$11,'01_input_asset_master'!H$2:H$11) -> 120000 | D5: =_xlfn.XLOOKUP(A5,'01_input_asset_master'!A$2:A$11,'01_input_asset_master'!I$2:I$11) -> 130 | E5: =SUMIFS('03_input_water_monthly'!G:G,'03_input_water_monthly'!A:A,A5) -> 32382.31 | F5: =SUMIFS('03_input_water_monthly'!H:H,'03_input_water_monthly'!A:A,A5) -> 39321.36 | G5: =SUMIFS('03_input_water_monthly'!H:H,'03_input_water_monthly'!A:A,A5) -> 39321.36 | H5: =F5+G5 -> 78642.72 | I5: =E5/C5 -> 0.26985258 | J5: =E5/D5 -> 249.09469 | K5: =H5/D5 -> 604.944 | L5: =H5/C5 -> 0.655356 | M5: =COUNTIFS('03_input_water_monthly'!A:A,A5,'03_input_water_monthly'!E:E,">0") -> 12 | N5: =M5/12 -> 1 | O5: =IF(J5>75000,"High Water Use",IF(J5>55000,"Moderate","Efficient/Low")) -> Efficient/Low | P5: =IF(K5>700,"High Cost",IF(K5>500,"Moderate Cost","Low Cost")) -> Moderate Cost | Q5: =IF(O5="High Water Use","Leak detection + low-flow fixtures + irrigation review",IF(O5="Moderate","Monitor usage + fixture review","Maintain performance")) -> Maintain performance | R5: =_xlfn.RANK.EQ(K5,$K$2:$K$11,0) -> 5 | S5: =_xlfn.RANK.EQ(I5,$I$2:$I$11,0) -> 5 | T5: =_xlfn.RANK.EQ(J5,$J$2:$J$11,0)+_xlfn.RANK.EQ(K5,$K$2:$K$11,0) -> 10 | U5: =_xlfn.RANK.EQ(J5,$J$2:$J$11,0)+_xlfn.RANK.EQ(K5,$K$2:$K$11,0) -> 10
A6: WI-MF-05 | B6: =_xlfn.XLOOKUP(A6,'01_input_asset_master'!A$2:A$11,'01_input_asset_master'!B$2:B$11) -> Oak Street Lofts | C6: =_xlfn.XLOOKUP(A6,'01_input_asset_master'!A$2:A$11,'01_input_asset_master'!H$2:H$11) -> 98000 | D6: =_xlfn.XLOOKUP(A6,'01_input_asset_master'!A$2:A$11,'01_input_asset_master'!I$2:I$11) -> 105 | E6: =SUMIFS('03_input_water_monthly'!G:G,'03_input_water_monthly'!A:A,A6) -> 20938.79 | F6: =SUMIFS('03_input_water_monthly'!H:H,'03_input_water_monthly'!A:A,A6) -> 25425.67 | G6: =SUMIFS('03_input_water_monthly'!H:H,'03_input_water_monthly'!A:A,A6) -> 25425.67 | H6: =F6+G6 -> 50851.34 | I6: =E6/C6 -> 0.21366112 | J6: =E6/D6 -> 199.41705 | K6: =H6/D6 -> 484.29848 | L6: =H6/C6 -> 0.51889122 | M6: =COUNTIFS('03_input_water_monthly'!A:A,A6,'03_input_water_monthly'!E:E,">0") -> 12 | N6: =M6/12 -> 1 | O6: =IF(J6>75000,"High Water Use",IF(J6>55000,"Moderate","Efficient/Low")) -> Efficient/Low | P6: =IF(K6>700,"High Cost",IF(K6>500,"Moderate Cost","Low Cost")) -> Low Cost | Q6: =IF(O6="High Water Use","Leak detection + low-flow fixtures + irrigation review",IF(O6="Moderate","Monitor usage + fixture review","Maintain performance")) -> Maintain performance | R6: =_xlfn.RANK.EQ(K6,$K$2:$K$11,0) -> 10 | S6: =_xlfn.RANK.EQ(I6,$I$2:$I$11,0) -> 10 | T6: =_xlfn.RANK.EQ(J6,$J$2:$J$11,0)+_xlfn.RANK.EQ(K6,$K$2:$K$11,0) -> 20 | U6: =_xlfn.RANK.EQ(J6,$J$2:$J$11,0)+_xlfn.RANK.EQ(K6,$K$2:$K$11,0) -> 20
A7: WI-MF-06 | B7: =_xlfn.XLOOKUP(A7,'01_input_asset_master'!A$2:A$11,'01_input_asset_master'!B$2:B$11) -> South Park Apartments | C7: =_xlfn.XLOOKUP(A7,'01_input_asset_master'!A$2:A$11,'01_input_asset_master'!H$2:H$11) -> 185000 | D7: =_xlfn.XLOOKUP(A7,'01_input_asset_master'!A$2:A$11,'01_input_asset_master'!I$2:I$11) -> 210 | E7: =SUMIFS('03_input_water_monthly'!G:G,'03_input_water_monthly'!A:A,A7) -> 66315.92 | F7: =SUMIFS('03_input_water_monthly'!H:H,'03_input_water_monthly'!A:A,A7) -> 80526.49 | G7: =SUMIFS('03_input_water_monthly'!H:H,'03_input_water_monthly'!A:A,A7) -> 80526.49 | H7: =F7+G7 -> 161052.98 | I7: =E7/C7 -> 0.35846443 | J7: =E7/D7 -> 315.7901 | K7: =H7/D7 -> 766.91895 | L7: =H7/C7 -> 0.87055665 | M7: =COUNTIFS('03_input_water_monthly'!A:A,A7,'03_input_water_monthly'!E:E,">0") -> 12 | N7: =M7/12 -> 1 | O7: =IF(J7>75000,"High Water Use",IF(J7>55000,"Moderate","Efficient/Low")) -> Efficient/Low | P7: =IF(K7>700,"High Cost",IF(K7>500,"Moderate Cost","Low Cost")) -> High Cost | Q7: =IF(O7="High Water Use","Leak detection + low-flow fixtures + irrigation review",IF(O7="Moderate","Monitor usage + fixture review","Maintain performance")) -> Maintain performance | R7: =_xlfn.RANK.EQ(K7,$K$2:$K$11,0) -> 2 | S7: =_xlfn.RANK.EQ(I7,$I$2:$I$11,0) -> 2 | T7: =_xlfn.RANK.EQ(J7,$J$2:$J$11,0)+_xlfn.RANK.EQ(K7,$K$2:$K$11,0) -> 4 | U7: =_xlfn.RANK.EQ(J7,$J$2:$J$11,0)+_xlfn.RANK.EQ(K7,$K$2:$K$11,0) -> 4
A8: WI-MF-07 | B8: =_xlfn.XLOOKUP(A8,'01_input_asset_master'!A$2:A$11,'01_input_asset_master'!B$2:B$11) -> Fox River Flats | C8: =_xlfn.XLOOKUP(A8,'01_input_asset_master'!A$2:A$11,'01_input_asset_master'!H$2:H$11) -> 135000 | D8: =_xlfn.XLOOKUP(A8,'01_input_asset_master'!A$2:A$11,'01_input_asset_master'!I$2:I$11) -> 150 | E8: =SUMIFS('03_input_water_monthly'!G:G,'03_input_water_monthly'!A:A,A8) -> 31331.91 | F8: =SUMIFS('03_input_water_monthly'!H:H,'03_input_water_monthly'!A:A,A8) -> 38045.88 | G8: =SUMIFS('03_input_water_monthly'!H:H,'03_input_water_monthly'!A:A,A8) -> 38045.88 | H8: =F8+G8 -> 76091.76 | I8: =E8/C8 -> 0.23208822 | J8: =E8/D8 -> 208.8794 | K8: =H8/D8 -> 507.2784 | L8: =H8/C8 -> 0.56364267 | M8: =COUNTIFS('03_input_water_monthly'!A:A,A8,'03_input_water_monthly'!E:E,">0") -> 12 | N8: =M8/12 -> 1 | O8: =IF(J8>75000,"High Water Use",IF(J8>55000,"Moderate","Efficient/Low")) -> Efficient/Low | P8: =IF(K8>700,"High Cost",IF(K8>500,"Moderate Cost","Low Cost")) -> Moderate Cost | Q8: =IF(O8="High Water Use","Leak detection + low-flow fixtures + irrigation review",IF(O8="Moderate","Monitor usage + fixture review","Maintain performance")) -> Maintain performance | R8: =_xlfn.RANK.EQ(K8,$K$2:$K$11,0) -> 8 | S8: =_xlfn.RANK.EQ(I8,$I$2:$I$11,0) -> 8 | T8: =_xlfn.RANK.EQ(J8,$J$2:$J$11,0)+_xlfn.RANK.EQ(K8,$K$2:$K$11,0) -> 16 | U8: =_xlfn.RANK.EQ(J8,$J$2:$J$11,0)+_xlfn.RANK.EQ(K8,$K$2:$K$11,0) -> 16
A9: WI-MF-08 | B9: =_xlfn.XLOOKUP(A9,'01_input_asset_master'!A$2:A$11,'01_input_asset_master'!B$2:B$11) -> Prairie View Residences | C9: =_xlfn.XLOOKUP(A9,'01_input_asset_master'!A$2:A$11,'01_input_asset_master'!H$2:H$11) -> 110000 | D9: =_xlfn.XLOOKUP(A9,'01_input_asset_master'!A$2:A$11,'01_input_asset_master'!I$2:I$11) -> 120 | E9: =SUMIFS('03_input_water_monthly'!G:G,'03_input_water_monthly'!A:A,A9) -> 27447.84 | F9: =SUMIFS('03_input_water_monthly'!H:H,'03_input_water_monthly'!A:A,A9) -> 33329.51 | G9: =SUMIFS('03_input_water_monthly'!H:H,'03_input_water_monthly'!A:A,A9) -> 33329.51 | H9: =F9+G9 -> 66659.02 | I9: =E9/C9 -> 0.24952582 | J9: =E9/D9 -> 228.732 | K9: =H9/D9 -> 555.49183 | L9: =H9/C9 -> 0.60599109 | M9: =COUNTIFS('03_input_water_monthly'!A:A,A9,'03_input_water_monthly'!E:E,">0") -> 12 | N9: =M9/12 -> 1 | O9: =IF(J9>75000,"High Water Use",IF(J9>55000,"Moderate","Efficient/Low")) -> Efficient/Low | P9: =IF(K9>700,"High Cost",IF(K9>500,"Moderate Cost","Low Cost")) -> Moderate Cost | Q9: =IF(O9="High Water Use","Leak detection + low-flow fixtures + irrigation review",IF(O9="Moderate","Monitor usage + fixture review","Maintain performance")) -> Maintain performance | R9: =_xlfn.RANK.EQ(K9,$K$2:$K$11,0) -> 7 | S9: =_xlfn.RANK.EQ(I9,$I$2:$I$11,0) -> 7 | T9: =_xlfn.RANK.EQ(J9,$J$2:$J$11,0)+_xlfn.RANK.EQ(K9,$K$2:$K$11,0) -> 14 | U9: =_xlfn.RANK.EQ(J9,$J$2:$J$11,0)+_xlfn.RANK.EQ(K9,$K$2:$K$11,0) -> 14
A10: WI-MF-09 | B10: =_xlfn.XLOOKUP(A10,'01_input_asset_master'!A$2:A$11,'01_input_asset_master'!B$2:B$11) -> Capitol Square Homes | C10: =_xlfn.XLOOKUP(A10,'01_input_asset_master'!A$2:A$11,'01_input_asset_master'!H$2:H$11) -> 175000 | D10: =_xlfn.XLOOKUP(A10,'01_input_asset_master'!A$2:A$11,'01_input_asset_master'!I$2:I$11) -> 190 | E10: =SUMIFS('03_input_water_monthly'!G:G,'03_input_water_monthly'!A:A,A10) -> 38401.79 | F10: =SUMIFS('03_input_water_monthly'!H:H,'03_input_water_monthly'!A:A,A10) -> 46630.74 | G10: =SUMIFS('03_input_water_monthly'!H:H,'03_input_water_monthly'!A:A,A10) -> 46630.74 | H10: =F10+G10 -> 93261.48 | I10: =E10/C10 -> 0.2194388 | J10: =E10/D10 -> 202.11468 | K10: =H10/D10 -> 490.84989 | L10: =H10/C10 -> 0.53292274 | M10: =COUNTIFS('03_input_water_monthly'!A:A,A10,'03_input_water_monthly'!E:E,">0") -> 12 | N10: =M10/12 -> 1 | O10: =IF(J10>75000,"High Water Use",IF(J10>55000,"Moderate","Efficient/Low")) -> Efficient/Low | P10: =IF(K10>700,"High Cost",IF(K10>500,"Moderate Cost","Low Cost")) -> Low Cost | Q10: =IF(O10="High Water Use","Leak detection + low-flow fixtures + irrigation review",IF(O10="Moderate","Monitor usage + fixture review","Maintain performance")) -> Maintain performance | R10: =_xlfn.RANK.EQ(K10,$K$2:$K$11,0) -> 9 | S10: =_xlfn.RANK.EQ(I10,$I$2:$I$11,0) -> 9 | T10: =_xlfn.RANK.EQ(J10,$J$2:$J$11,0)+_xlfn.RANK.EQ(K10,$K$2:$K$11,0) -> 18 | U10: =_xlfn.RANK.EQ(J10,$J$2:$J$11,0)+_xlfn.RANK.EQ(K10,$K$2:$K$11,0) -> 18
A11: WI-MF-10 | B11: =_xlfn.XLOOKUP(A11,'01_input_asset_master'!A$2:A$11,'01_input_asset_master'!B$2:B$11) -> Harbor Point Apartments | C11: =_xlfn.XLOOKUP(A11,'01_input_asset_master'!A$2:A$11,'01_input_asset_master'!H$2:H$11) -> 160000 | D11: =_xlfn.XLOOKUP(A11,'01_input_asset_master'!A$2:A$11,'01_input_asset_master'!I$2:I$11) -> 175 | E11: =SUMIFS('03_input_water_monthly'!G:G,'03_input_water_monthly'!A:A,A11) -> 53206.6 | F11: =SUMIFS('03_input_water_monthly'!H:H,'03_input_water_monthly'!A:A,A11) -> 64608.01 | G11: =SUMIFS('03_input_water_monthly'!H:H,'03_input_water_monthly'!A:A,A11) -> 64608.01 | H11: =F11+G11 -> 129216.02 | I11: =E11/C11 -> 0.33254125 | J11: =E11/D11 -> 304.03771 | K11: =H11/D11 -> 738.37726 | L11: =H11/C11 -> 0.80760012 | M11: =COUNTIFS('03_input_water_monthly'!A:A,A11,'03_input_water_monthly'!E:E,">0") -> 12 | N11: =M11/12 -> 1 | O11: =IF(J11>75000,"High Water Use",IF(J11>55000,"Moderate","Efficient/Low")) -> Efficient/Low | P11: =IF(K11>700,"High Cost",IF(K11>500,"Moderate Cost","Low Cost")) -> High Cost | Q11: =IF(O11="High Water Use","Leak detection + low-flow fixtures + irrigation review",IF(O11="Moderate","Monitor usage + fixture review","Maintain performance")) -> Maintain performance | R11: =_xlfn.RANK.EQ(K11,$K$2:$K$11,0) -> 3 | S11: =_xlfn.RANK.EQ(I11,$I$2:$I$11,0) -> 3 | T11: =_xlfn.RANK.EQ(J11,$J$2:$J$11,0)+_xlfn.RANK.EQ(K11,$K$2:$K$11,0) -> 6 | U11: =_xlfn.RANK.EQ(J11,$J$2:$J$11,0)+_xlfn.RANK.EQ(K11,$K$2:$K$11,0) -> 6
G20: =SUM('03_input_water_monthly'!D:D) -> 0

Sheet 04_input_waste_monthly
A1: property_id | B1: property_name | C1: city | D1: month | E1: landfill_tons | F1: recycling_tons | G1: compost_tons | H1: waste_cost_usd | I1: vendor | J1: data_quality | K1: source_note | L1: county | M1: state
A2: WI-MF-01 | B2: Riverbend Apartments | C2: Madison | D2: 2025-01 | E2: 9.45 | F2: 2.57 | G2: 0.26 | H2: 2167 | I2: Waste Management | J2: Actual | K2: Simulated property-level waste stream; structure aligns with ENERGY STAR Portfolio Manager waste tracking and EPA WARM materials-management categories. | L2: Dane | M2: WI
A3: WI-MF-01 | B3: Riverbend Apartments | C3: Madison | D3: 2025-02 | E3: 8.72 | F3: 2.23 | G3: 0.15 | H3: 1789 | I3: Waste Management | J3: Actual | K3: Simulated property-level waste stream; structure aligns with ENERGY STAR Portfolio Manager waste tracking and EPA WARM materials-management categories. | L3: Dane | M3: WI
A4: WI-MF-01 | B4: Riverbend Apartments | C4: Madison | D4: 2025-03 | E4: 9.44 | F4: 2.1 | G4: 0.18 | H4: 2008 | I4: Waste Management | J4: Actual | K4: Simulated property-level waste stream; structure aligns with ENERGY STAR Portfolio Manager waste tracking and EPA WARM materials-management categories. | L4: Dane | M4: WI
A5: WI-MF-01 | B5: Riverbend Apartments | C5: Madison | D5: 2025-04 | E5: 9.55 | F5: 2.22 | G5: 0.24 | H5: 2099 | I5: Waste Management | J5: Actual | K5: Simulated property-level waste stream; structure aligns with ENERGY STAR Portfolio Manager waste tracking and EPA WARM materials-management categories. | L5: Dane | M5: WI
A6: WI-MF-01 | B6: Riverbend Apartments | C6: Madison | D6: 2025-05 | E6: 9.33 | F6: 2.59 | G6: 0.26 | H6: 1964 | I6: Waste Management | J6: Actual | K6: Simulated property-level waste stream; structure aligns with ENERGY STAR Portfolio Manager waste tracking and EPA WARM materials-management categories. | L6: Dane | M6: WI
A7: WI-MF-01 | B7: Riverbend Apartments | C7: Madison | D7: 2025-06 | E7: 9.88 | F7: 2.92 | G7: 0.22 | H7: 1982 | I7: Waste Management | J7: Actual | K7: Simulated property-level waste stream; structure aligns with ENERGY STAR Portfolio Manager waste tracking and EPA WARM materials-management categories. | L7: Dane | M7: WI
A8: WI-MF-01 | B8: Riverbend Apartments | C8: Madison | D8: 2025-07 | E8: 9.55 | F8: 2.7 | G8: 0.25 | H8: 2168 | I8: Waste Management | J8: Actual | K8: Simulated property-level waste stream; structure aligns with ENERGY STAR Portfolio Manager waste tracking and EPA WARM materials-management categories. | L8: Dane | M8: WI
A9: WI-MF-01 | B9: Riverbend Apartments | C9: Madison | D9: 2025-08 | E9: 10.07 | F9: 2.53 | G9: 0.32 | H9: 2071 | I9: Waste Management | J9: Actual | K9: Simulated property-level waste stream; structure aligns with ENERGY STAR Portfolio Manager waste tracking and EPA WARM materials-management categories. | L9: Dane | M9: WI
A10: WI-MF-01 | B10: Riverbend Apartments | C10: Madison | D10: 2025-09 | E10: 9.37 | F10: 2.63 | G10: 0.25 | H10: 2152 | I10: Waste Management | J10: Actual | K10: Simulated property-level waste stream; structure aligns with ENERGY STAR Portfolio Manager waste tracking and EPA WARM materials-management categories. | L10: Dane | M10: WI
A11: WI-MF-01 | B11: Riverbend Apartments | C11: Madison | D11: 2025-10 | E11: 9.28 | F11: 2.59 | G11: 0.17 | H11: 1907 | I11: Waste Management | J11: Actual | K11: Simulated property-level waste stream; structure aligns with ENERGY STAR Portfolio Manager waste tracking and EPA WARM materials-management categories. | L11: Dane | M11: WI
A12: WI-MF-01 | B12: Riverbend Apartments | C12: Madison | D12: 2025-11 | E12: 9.81 | F12: 2.22 | G12: 0.2 | H12: 1888 | I12: Waste Management | J12: Actual | K12: Simulated property-level waste stream; structure aligns with ENERGY STAR Portfolio Manager waste tracking and EPA WARM materials-management categories. | L12: Dane | M12: WI
A13: WI-MF-01 | B13: Riverbend Apartments | C13: Madison | D13: 2025-12 | E13: 10.19 | F13: 2.74 | G13: 0.23 | H13: 2100 | I13: Waste Management | J13: Actual | K13: Simulated property-level waste stream; structure aligns with ENERGY STAR Portfolio Manager waste tracking and EPA WARM materials-management categories. | L13: Dane | M13: WI
... A121: WI-MF-10 | B121: Harbor Point Apartments | C121: Kenosha | D121: 2025-12 | E121: 10.32 | F121: 2.47 | G121: 0 | H121: 2114 | I121: Waste Management | J121: Estimated | K121: Simulated property-level waste stream; structure aligns with ENERGY STAR Portfolio Manager waste tracking and EPA WARM materials-management categories. | L121: Kenosha | M121: WI

Sheet 13_calc_waste_summary
A1: property_id | B1: property_name | C1: gross_floor_area_sqft | D1: units | E1: annual_landfill_tons | F1: annual_recycling_tons | G1: annual_compost_tons | H1: annual_total_waste_tons | I1: annual_waste_cost_usd | J1: diverted_waste_tons | K1: waste_diversion_rate | L1: waste_per_unit_tons | M1: waste_per_1000_sqft_tons | N1: waste_cost_per_unit | O1: waste_cost_per_sqft | P1: months_with_waste_data | Q1: waste_data_coverage_pct | R1: waste_performance_flag | S1: diversion_performance_flag | T1: recommended_waste_action | U1: waste_priority_rank | V1: diversion_priority_rank
A2: WI-MF-01 | B2: =_xlfn.XLOOKUP(A2,'01_input_asset_master'!A$2:A$11,'01_input_asset_master'!B$2:B$11) -> Riverbend Apartments | C2: =_xlfn.XLOOKUP(A2,'01_input_asset_master'!A$2:A$11,'01_input_asset_master'!H$2:H$11) -> 165000 | D2: =_xlfn.XLOOKUP(A2,'01_input_asset_master'!A$2:A$11,'01_input_asset_master'!I$2:I$11) -> 180 | E2: =SUMIFS(INDEX('04_input_waste_monthly'!$A:$Z,0,MATCH("landfill_tons",'04_input_waste_monthly'!$1:$1,0)),'04_input_waste_monthly'!$A:$A,A2) -> 114.64 | F2: =SUMIFS(INDEX('04_input_waste_monthly'!$A:$Z,0,MATCH("recycling_tons",'04_input_waste_monthly'!$1:$1,0)),'04_input_waste_monthly'!$A:$A,A2) -> 30.04 | G2: =SUMIFS(INDEX('04_input_waste_monthly'!$A:$Z,0,MATCH("compost_tons",'04_input_waste_monthly'!$1:$1,0)),'04_input_waste_monthly'!$A:$A,A2) -> 2.73 | H2: =E2+F2+G2 -> 147.41 | I2: =SUMIFS(INDEX('04_input_waste_monthly'!$A:$Z,0,MATCH("waste_cost_usd",'04_input_waste_monthly'!$1:$1,0)),'04_input_waste_monthly'!$A:$A,A2) -> 24295 | J2: =F2+G2 -> 32.77 | K2: =IF(H2=0,0,J2/H2) -> 0.22230514 | L2: =H2/D2 -> 0.81894444 | M2: =H2/(C2/1000) -> 0.89339394 | N2: =I2/D2 -> 134.97222 | O2: =I2/C2 -> 0.14724242 | P2: =COUNTIFS('04_input_waste_monthly'!$A:$A,A2,INDEX('04_input_waste_monthly'!$A:$Z,0,MATCH("landfill_tons",'04_input_waste_monthly'!$1:$1,0)),">0") -> 12 | Q2: =P2/12 -> 1 | R2: =IF(L2>0.8,"High Waste",IF(L2>0.5,"Moderate","Low")) -> High Waste | S2: =IF(K2>=0.5,"Strong Diversion",IF(K2>=0.3,"Moderate Diversion","Weak Diversion")) -> Weak Diversion | T2: =IF(AND(R2="High Waste",S2="Weak Diversion"),"Waste audit + recycling access + tenant education + vendor review",IF(S2="Weak Diversion","Improve recycling access + tenant education + vendor review",IF(R2="High Waste","Waste audit + contamination review + right-size bins","Maintain program + monitor diversion"))) -> Waste audit + recycling access + tenant education + vendor review | U2: =_xlfn.RANK.EQ(L2,$L$2:$L$11,0) -> 6 | V2: =_xlfn.RANK.EQ(K2,$K$2:$K$11,1) -> 5
A3: WI-MF-02 | B3: =_xlfn.XLOOKUP(A3,'01_input_asset_master'!A$2:A$11,'01_input_asset_master'!B$2:B$11) -> Lakeview Terrace | C3: =_xlfn.XLOOKUP(A3,'01_input_asset_master'!A$2:A$11,'01_input_asset_master'!H$2:H$11) -> 220000 | D3: =_xlfn.XLOOKUP(A3,'01_input_asset_master'!A$2:A$11,'01_input_asset_master'!I$2:I$11) -> 240 | E3: =SUMIFS(INDEX('04_input_waste_monthly'!$A:$Z,0,MATCH("landfill_tons",'04_input_waste_monthly'!$1:$1,0)),'04_input_waste_monthly'!$A:$A,A3) -> 163.27 | F3: =SUMIFS(INDEX('04_input_waste_monthly'!$A:$Z,0,MATCH("recycling_tons",'04_input_waste_monthly'!$1:$1,0)),'04_input_waste_monthly'!$A:$A,A3) -> 30.64 | G3: =SUMIFS(INDEX('04_input_waste_monthly'!$A:$Z,0,MATCH("compost_tons",'04_input_waste_monthly'!$1:$1,0)),'04_input_waste_monthly'!$A:$A,A3) -> 6.04 | H3: =E3+F3+G3 -> 199.95 | I3: =SUMIFS(INDEX('04_input_waste_monthly'!$A:$Z,0,MATCH("waste_cost_usd",'04_input_waste_monthly'!$1:$1,0)),'04_input_waste_monthly'!$A:$A,A3) -> 32107 | J3: =F3+G3 -> 36.68 | K3: =IF(H3=0,0,J3/H3) -> 0.18344586 | L3: =H3/D3 -> 0.833125 | M3: =H3/(C3/1000) -> 0.90886364 | N3: =I3/D3 -> 133.77917 | O3: =I3/C3 -> 0.14594091 | P3: =COUNTIFS('04_input_waste_monthly'!$A:$A,A3,INDEX('04_input_waste_monthly'!$A:$Z,0,MATCH("landfill_tons",'04_input_waste_monthly'!$1:$1,0)),">0") -> 12 | Q3: =P3/12 -> 1 | R3: =IF(L3>0.8,"High Waste",IF(L3>0.5,"Moderate","Low")) -> High Waste | S3: =IF(K3>=0.5,"Strong Diversion",IF(K3>=0.3,"Moderate Diversion","Weak Diversion")) -> Weak Diversion | T3: =IF(AND(R3="High Waste",S3="Weak Diversion"),"Waste audit + recycling access + tenant education + vendor review",IF(S3="Weak Diversion","Improve recycling access + tenant education + vendor review",IF(R3="High Waste","Waste audit + contamination review + right-size bins","Maintain program + monitor diversion"))) -> Waste audit + recycling access + tenant education + vendor review | U3: =_xlfn.RANK.EQ(L3,$L$2:$L$11,0) -> 3 | V3: =_xlfn.RANK.EQ(K3,$K$2:$K$11,1) -> 1
A4: WI-MF-03 | B4: =_xlfn.XLOOKUP(A4,'01_input_asset_master'!A$2:A$11,'01_input_asset_master'!B$2:B$11) -> Northside Commons | C4: =_xlfn.XLOOKUP(A4,'01_input_asset_master'!A$2:A$11,'01_input_asset_master'!H$2:H$11) -> 145000 | D4: =_xlfn.XLOOKUP(A4,'01_input_asset_master'!A$2:A$11,'01_input_asset_master'!I$2:I$11) -> 160 | E4: =SUMIFS(INDEX('04_input_waste_monthly'!$A:$Z,0,MATCH("landfill_tons",'04_input_waste_monthly'!$1:$1,0)),'04_input_waste_monthly'!$A:$A,A4) -> 95.26 | F4: =SUMIFS(INDEX('04_input_waste_monthly'!$A:$Z,0,MATCH("recycling_tons",'04_input_waste_monthly'!$1:$1,0)),'04_input_waste_monthly'!$A:$A,A4) -> 35.34 | G4: =SUMIFS(INDEX('04_input_waste_monthly'!$A:$Z,0,MATCH("compost_tons",'04_input_waste_monthly'!$1:$1,0)),'04_input_waste_monthly'!$A:$A,A4) -> 0 | H4: =E4+F4+G4 -> 130.6 | I4: =SUMIFS(INDEX('04_input_waste_monthly'!$A:$Z,0,MATCH("waste_cost_usd",'04_input_waste_monthly'!$1:$1,0)),'04_input_waste_monthly'!$A:$A,A4) -> 21834 | J4: =F4+G4 -> 35.34 | K4: =IF(H4=0,0,J4/H4) -> 0.27059724 | L4: =H4/D4 -> 0.81625 | M4: =H4/(C4/1000) -> 0.90068966 | N4: =I4/D4 -> 136.4625 | O4: =I4/C4 -> 0.15057931 | P4: =COUNTIFS('04_input_waste_monthly'!$A:$A,A4,INDEX('04_input_waste_monthly'!$A:$Z,0,MATCH("landfill_tons",'04_input_waste_monthly'!$1:$1,0)),">0") -> 12 | Q4: =P4/12 -> 1 | R4: =IF(L4>0.8,"High Waste",IF(L4>0.5,"Moderate","Low")) -> High Waste | S4: =IF(K4>=0.5,"Strong Diversion",IF(K4>=0.3,"Moderate Diversion","Weak Diversion")) -> Weak Diversion | T4: =IF(AND(R4="High Waste",S4="Weak Diversion"),"Waste audit + recycling access + tenant education + vendor review",IF(S4="Weak Diversion","Improve recycling access + tenant education + vendor review",IF(R4="High Waste","Waste audit + contamination review + right-size bins","Maintain program + monitor diversion"))) -> Waste audit + recycling access + tenant education + vendor review | U4: =_xlfn.RANK.EQ(L4,$L$2:$L$11,0) -> 7 | V4: =_xlfn.RANK.EQ(K4,$K$2:$K$11,1) -> 8 | X4: Waste analysis shows that the portfolio has complete waste data coverage, with 12 months of data available for each property. However, most properties show high waste generation per unit and weak diversion performance. South Park Apartments, Badger Ridge Homes, Lakeview Terrace, Capitol Square Homes, and Oak Street Lofts have the highest waste per unit and should be prioritized for waste audits. Diversion performance is especially weak at Lakeview Terrace, Harbor Point Apartments, South Park Apartments, Badger Ridge Homes, and Riverbend Apartments, suggesting a need for improved recycling access, tenant education, contamination review, and vendor coordination.
A5: WI-MF-04 | B5: =_xlfn.XLOOKUP(A5,'01_input_asset_master'!A$2:A$11,'01_input_asset_master'!B$2:B$11) -> Badger Ridge Homes | C5: =_xlfn.XLOOKUP(A5,'01_input_asset_master'!A$2:A$11,'01_input_asset_master'!H$2:H$11) -> 120000 | D5: =_xlfn.XLOOKUP(A5,'01_input_asset_master'!A$2:A$11,'01_input_asset_master'!I$2:I$11) -> 130 | E5: =SUMIFS(INDEX('04_input_waste_monthly'!$A:$Z,0,MATCH("landfill_tons",'04_input_waste_monthly'!$1:$1,0)),'04_input_waste_monthly'!$A:$A,A5) -> 85.29 | F5: =SUMIFS(INDEX('04_input_waste_monthly'!$A:$Z,0,MATCH("recycling_tons",'04_input_waste_monthly'!$1:$1,0)),'04_input_waste_monthly'!$A:$A,A5) -> 23.91 | G5: =SUMIFS(INDEX('04_input_waste_monthly'!$A:$Z,0,MATCH("compost_tons",'04_input_waste_monthly'!$1:$1,0)),'04_input_waste_monthly'!$A:$A,A5) -> 0 | H5: =E5+F5+G5 -> 109.2 | I5: =SUMIFS(INDEX('04_input_waste_monthly'!$A:$Z,0,MATCH("waste_cost_usd",'04_input_waste_monthly'!$1:$1,0)),'04_input_waste_monthly'!$A:$A,A5) -> 18459 | J5: =F5+G5 -> 23.91 | K5: =IF(H5=0,0,J5/H5) -> 0.21895604 | L5: =H5/D5 -> 0.84 | M5: =H5/(C5/1000) -> 0.91 | N5: =I5/D5 -> 141.99231 | O5: =I5/C5 -> 0.153825 | P5: =COUNTIFS('04_input_waste_monthly'!$A:$A,A5,INDEX('04_input_waste_monthly'!$A:$Z,0,MATCH("landfill_tons",'04_input_waste_monthly'!$1:$1,0)),">0") -> 12 | Q5: =P5/12 -> 1 | R5: =IF(L5>0.8,"High Waste",IF(L5>0.5,"Moderate","Low")) -> High Waste | S5: =IF(K5>=0.5,"Strong Diversion",IF(K5>=0.3,"Moderate Diversion","Weak Diversion")) -> Weak Diversion | T5: =IF(AND(R5="High Waste",S5="Weak Diversion"),"Waste audit + recycling access + tenant education + vendor review",IF(S5="Weak Diversion","Improve recycling access + tenant education + vendor review",IF(R5="High Waste","Waste audit + contamination review + right-size bins","Maintain program + monitor diversion"))) -> Waste audit + recycling access + tenant education + vendor review | U5: =_xlfn.RANK.EQ(L5,$L$2:$L$11,0) -> 2 | V5: =_xlfn.RANK.EQ(K5,$K$2:$K$11,1) -> 4
